Traceback (most recent call last):
  File "<frozen runpy>", line 198, in _run_module_as_main
  File "<frozen runpy>", line 88, in _run_code
  File "/hpc/group/naderilab/imt11/antibody-domainbed/domainbed/scripts/train.py", line 169, in <module>
    algorithm = algorithm_class(dataset.input_shape, dataset.num_classes,
                ^^^^^^^^^^^^^^^^^^^^^^^^^^^^^^^^^^^^^^^^^^^^^^^^^^^^^^^^^
  File "/hpc/group/naderilab/imt11/antibody-domainbed/domainbed/algorithms.py", line 99, in __init__
    self.featurizer = networks.Featurizer(input_shape, self.hparams)
                      ^^^^^^^^^^^^^^^^^^^^^^^^^^^^^^^^^^^^^^^^^^^^^^
  File "/hpc/group/naderilab/imt11/antibody-domainbed/domainbed/networks.py", line 59, in Featurizer
    return SeqCNN(input_shape[0], hparams)
                  ~~~~~~~~~~~^^^
TypeError: 'NoneType' object is not subscriptable
Traceback (most recent call last):
  File "<frozen runpy>", line 198, in _run_module_as_main
  File "<frozen runpy>", line 88, in _run_code
  File "/hpc/group/naderilab/imt11/antibody-domainbed/domainbed/scripts/train.py", line 169, in <module>
    algorithm = algorithm_class(dataset.input_shape, dataset.num_classes,
                ^^^^^^^^^^^^^^^^^^^^^^^^^^^^^^^^^^^^^^^^^^^^^^^^^^^^^^^^^
  File "/hpc/group/naderilab/imt11/antibody-domainbed/domainbed/algorithms.py", line 99, in __init__
    self.featurizer = networks.Featurizer(input_shape, self.hparams)
                      ^^^^^^^^^^^^^^^^^^^^^^^^^^^^^^^^^^^^^^^^^^^^^^
  File "/hpc/group/naderilab/imt11/antibody-domainbed/domainbed/networks.py", line 59, in Featurizer
    return SeqCNN(input_shape[0], hparams)
                  ~~~~~~~~~~~^^^
TypeError: 'NoneType' object is not subscriptable
Traceback (most recent call last):
  File "<frozen runpy>", line 198, in _run_module_as_main
  File "<frozen runpy>", line 88, in _run_code
  File "/hpc/group/naderilab/imt11/antibody-domainbed/domainbed/scripts/train.py", line 111, in <module>
    dataset = vars(datasets)[args.dataset](
              ^^^^^^^^^^^^^^^^^^^^^^^^^^^^^
  File "/hpc/group/naderilab/imt11/antibody-domainbed/domainbed/datasets.py", line 181, in __init__
    df.drop_duplicates(subset=['seqid'], inplace=True, keep='last')
  File "/hpc/group/naderilab/imt11/Miniconda3/lib/python3.12/site-packages/pandas/core/frame.py", line 6818, in drop_duplicates
    result = self[-self.duplicated(subset, keep=keep)]
                   ^^^^^^^^^^^^^^^^^^^^^^^^^^^^^^^^^^
  File "/hpc/group/naderilab/imt11/Miniconda3/lib/python3.12/site-packages/pandas/core/frame.py", line 6950, in duplicated
    raise KeyError(Index(diff))
KeyError: Index(['seqid'], dtype='object')
Traceback (most recent call last):
  File "<frozen runpy>", line 198, in _run_module_as_main
  File "<frozen runpy>", line 88, in _run_code
  File "/hpc/group/naderilab/imt11/antibody-domainbed/domainbed/scripts/train.py", line 111, in <module>
    dataset = vars(datasets)[args.dataset](
              ^^^^^^^^^^^^^^^^^^^^^^^^^^^^^
  File "/hpc/group/naderilab/imt11/antibody-domainbed/domainbed/datasets.py", line 181, in __init__
    df.drop_duplicates(subset=['seqid'], inplace=True, keep='last')
  File "/hpc/group/naderilab/imt11/Miniconda3/lib/python3.12/site-packages/pandas/core/frame.py", line 6818, in drop_duplicates
    result = self[-self.duplicated(subset, keep=keep)]
                   ^^^^^^^^^^^^^^^^^^^^^^^^^^^^^^^^^^
  File "/hpc/group/naderilab/imt11/Miniconda3/lib/python3.12/site-packages/pandas/core/frame.py", line 6950, in duplicated
    raise KeyError(Index(diff))
KeyError: Index(['seqid'], dtype='object')
Traceback (most recent call last):
  File "/hpc/group/naderilab/imt11/Miniconda3/lib/python3.12/site-packages/pandas/core/indexes/base.py", line 3805, in get_loc
    return self._engine.get_loc(casted_key)
           ^^^^^^^^^^^^^^^^^^^^^^^^^^^^^^^^
  File "index.pyx", line 167, in pandas._libs.index.IndexEngine.get_loc
  File "index.pyx", line 196, in pandas._libs.index.IndexEngine.get_loc
  File "pandas/_libs/hashtable_class_helper.pxi", line 7081, in pandas._libs.hashtable.PyObjectHashTable.get_item
  File "pandas/_libs/hashtable_class_helper.pxi", line 7089, in pandas._libs.hashtable.PyObjectHashTable.get_item
KeyError: 'ag_wt'

The above exception was the direct cause of the following exception:

Traceback (most recent call last):
  File "<frozen runpy>", line 198, in _run_module_as_main
  File "<frozen runpy>", line 88, in _run_code
  File "/hpc/group/naderilab/imt11/antibody-domainbed/domainbed/scripts/train.py", line 111, in <module>
    dataset = vars(datasets)[args.dataset](
              ^^^^^^^^^^^^^^^^^^^^^^^^^^^^^
  File "/hpc/group/naderilab/imt11/antibody-domainbed/domainbed/datasets.py", line 189, in __init__
    target_len = df['ag_wt'].apply(len)
                 ~~^^^^^^^^^
  File "/hpc/group/naderilab/imt11/Miniconda3/lib/python3.12/site-packages/pandas/core/frame.py", line 4102, in __getitem__
    indexer = self.columns.get_loc(key)
              ^^^^^^^^^^^^^^^^^^^^^^^^^
  File "/hpc/group/naderilab/imt11/Miniconda3/lib/python3.12/site-packages/pandas/core/indexes/base.py", line 3812, in get_loc
    raise KeyError(key) from err
KeyError: 'ag_wt'
