Environment:
	Python: 3.12.8
	PyTorch: 2.6.0+cu124
	CUDA: 12.4
	CUDNN: 90100
	NumPy: 2.2.2
	PIL: 11.1.0
Args:
	algorithm: ERM
	checkpoint_freq: None
	data_dir: .
	dataset: AbRosetta
	holdout_fraction: 0.2
	hparams: None
	hparams_seed: 0
	init_step: False
	output_dir: outputs
	path_for_init: None
	save_model_every_checkpoint: False
	seed: 0
	skip_model_save: False
	steps: None
	target: None
	task: domain_generalization
	test_envs: [0]
	trial_seed: 0
	uda_holdout_fraction: 0
	use_esm: False
HParams:
	add_noise: False
	batch_size: 32
	class_balanced: False
	data_augmentation: True
	lr: 5e-05
	nonlinear_classifier: False
	resnet18: True
	resnet_dropout: 0.0
	weight_decay: 0.0
Device:  cuda
Error loading the dataset, was it downloaded?
Traceback (most recent call last):
  File "<frozen runpy>", line 198, in _run_module_as_main
  File "<frozen runpy>", line 88, in _run_code
  File "/hpc/group/naderilab/imt11/antibody-domainbed/domainbed/scripts/train.py", line 169, in <module>
    algorithm = algorithm_class(dataset.input_shape, dataset.num_classes,
                ^^^^^^^^^^^^^^^^^^^^^^^^^^^^^^^^^^^^^^^^^^^^^^^^^^^^^^^^^
  File "/hpc/group/naderilab/imt11/antibody-domainbed/domainbed/algorithms.py", line 99, in __init__
    self.featurizer = networks.Featurizer(input_shape, self.hparams)
                      ^^^^^^^^^^^^^^^^^^^^^^^^^^^^^^^^^^^^^^^^^^^^^^
  File "/hpc/group/naderilab/imt11/antibody-domainbed/domainbed/networks.py", line 59, in Featurizer
    return SeqCNN(input_shape[0], hparams)
                  ~~~~~~~~~~~^^^
TypeError: 'NoneType' object is not subscriptable
Environment:
	Python: 3.12.8
	PyTorch: 2.6.0+cu124
	CUDA: 12.4
	CUDNN: 90100
	NumPy: 2.2.2
	PIL: 11.1.0
Args:
	algorithm: ERM
	checkpoint_freq: None
	data_dir: .
	dataset: AbRosetta
	holdout_fraction: 0.2
	hparams: None
	hparams_seed: 0
	init_step: False
	output_dir: outputs
	path_for_init: None
	save_model_every_checkpoint: False
	seed: 0
	skip_model_save: False
	steps: None
	target: None
	task: domain_generalization
	test_envs: [0]
	trial_seed: 0
	uda_holdout_fraction: 0
	use_esm: False
HParams:
	add_noise: False
	batch_size: 32
	class_balanced: False
	data_augmentation: True
	lr: 5e-05
	nonlinear_classifier: False
	resnet18: True
	resnet_dropout: 0.0
	weight_decay: 0.0
Device:  cuda
Error loading the dataset, was it downloaded?
Traceback (most recent call last):
  File "<frozen runpy>", line 198, in _run_module_as_main
  File "<frozen runpy>", line 88, in _run_code
  File "/hpc/group/naderilab/imt11/antibody-domainbed/domainbed/scripts/train.py", line 169, in <module>
    algorithm = algorithm_class(dataset.input_shape, dataset.num_classes,
                ^^^^^^^^^^^^^^^^^^^^^^^^^^^^^^^^^^^^^^^^^^^^^^^^^^^^^^^^^
  File "/hpc/group/naderilab/imt11/antibody-domainbed/domainbed/algorithms.py", line 99, in __init__
    self.featurizer = networks.Featurizer(input_shape, self.hparams)
                      ^^^^^^^^^^^^^^^^^^^^^^^^^^^^^^^^^^^^^^^^^^^^^^
  File "/hpc/group/naderilab/imt11/antibody-domainbed/domainbed/networks.py", line 59, in Featurizer
    return SeqCNN(input_shape[0], hparams)
                  ~~~~~~~~~~~^^^
TypeError: 'NoneType' object is not subscriptable
Environment:
	Python: 3.12.8
	PyTorch: 2.6.0+cu124
	CUDA: 12.4
	CUDNN: 90100
	NumPy: 2.2.2
	PIL: 11.1.0
Args:
	algorithm: ERM
	checkpoint_freq: None
	data_dir: .
	dataset: AbRosetta
	holdout_fraction: 0.2
	hparams: None
	hparams_seed: 0
	init_step: False
	output_dir: outputs
	path_for_init: None
	save_model_every_checkpoint: False
	seed: 0
	skip_model_save: False
	steps: None
	target: None
	task: domain_generalization
	test_envs: [0]
	trial_seed: 0
	uda_holdout_fraction: 0
	use_esm: False
HParams:
	add_noise: False
	batch_size: 32
	class_balanced: False
	data_augmentation: True
	lr: 5e-05
	nonlinear_classifier: False
	resnet18: True
	resnet_dropout: 0.0
	weight_decay: 0.0
Device:  cuda
Loading dataset from domainbed/data/abdb.csv
Traceback (most recent call last):
  File "<frozen runpy>", line 198, in _run_module_as_main
  File "<frozen runpy>", line 88, in _run_code
  File "/hpc/group/naderilab/imt11/antibody-domainbed/domainbed/scripts/train.py", line 111, in <module>
    dataset = vars(datasets)[args.dataset](
              ^^^^^^^^^^^^^^^^^^^^^^^^^^^^^
  File "/hpc/group/naderilab/imt11/antibody-domainbed/domainbed/datasets.py", line 181, in __init__
    df.drop_duplicates(subset=['seqid'], inplace=True, keep='last')
  File "/hpc/group/naderilab/imt11/Miniconda3/lib/python3.12/site-packages/pandas/core/frame.py", line 6818, in drop_duplicates
    result = self[-self.duplicated(subset, keep=keep)]
                   ^^^^^^^^^^^^^^^^^^^^^^^^^^^^^^^^^^
  File "/hpc/group/naderilab/imt11/Miniconda3/lib/python3.12/site-packages/pandas/core/frame.py", line 6950, in duplicated
    raise KeyError(Index(diff))
KeyError: Index(['seqid'], dtype='object')
Environment:
	Python: 3.12.8
	PyTorch: 2.6.0+cu124
	CUDA: 12.4
	CUDNN: 90100
	NumPy: 2.2.2
	PIL: 11.1.0
Args:
	algorithm: ERM
	checkpoint_freq: None
	data_dir: .
	dataset: AbRosetta
	holdout_fraction: 0.2
	hparams: None
	hparams_seed: 0
	init_step: False
	output_dir: outputs/
	path_for_init: None
	save_model_every_checkpoint: False
	seed: 0
	skip_model_save: False
	steps: None
	target: None
	task: domain_generalization
	test_envs: [0]
	trial_seed: 0
	uda_holdout_fraction: 0
	use_esm: False
HParams:
	add_noise: False
	batch_size: 32
	class_balanced: False
	data_augmentation: True
	lr: 5e-05
	nonlinear_classifier: False
	resnet18: True
	resnet_dropout: 0.0
	weight_decay: 0.0
Device:  cuda
Loading dataset from domainbed/data/abdb.csv
Traceback (most recent call last):
  File "<frozen runpy>", line 198, in _run_module_as_main
  File "<frozen runpy>", line 88, in _run_code
  File "/hpc/group/naderilab/imt11/antibody-domainbed/domainbed/scripts/train.py", line 111, in <module>
    dataset = vars(datasets)[args.dataset](
              ^^^^^^^^^^^^^^^^^^^^^^^^^^^^^
  File "/hpc/group/naderilab/imt11/antibody-domainbed/domainbed/datasets.py", line 181, in __init__
    df.drop_duplicates(subset=['seqid'], inplace=True, keep='last')
  File "/hpc/group/naderilab/imt11/Miniconda3/lib/python3.12/site-packages/pandas/core/frame.py", line 6818, in drop_duplicates
    result = self[-self.duplicated(subset, keep=keep)]
                   ^^^^^^^^^^^^^^^^^^^^^^^^^^^^^^^^^^
  File "/hpc/group/naderilab/imt11/Miniconda3/lib/python3.12/site-packages/pandas/core/frame.py", line 6950, in duplicated
    raise KeyError(Index(diff))
KeyError: Index(['seqid'], dtype='object')
Environment:
	Python: 3.12.8
	PyTorch: 2.6.0+cu124
	CUDA: 12.4
	CUDNN: 90100
	NumPy: 2.2.2
	PIL: 11.1.0
Args:
	algorithm: ERM
	checkpoint_freq: None
	data_dir: .
	dataset: AbRosetta
	holdout_fraction: 0.2
	hparams: None
	hparams_seed: 0
	init_step: False
	output_dir: outputs/
	path_for_init: None
	save_model_every_checkpoint: False
	seed: 0
	skip_model_save: False
	steps: None
	target: None
	task: domain_generalization
	test_envs: [0]
	trial_seed: 0
	uda_holdout_fraction: 0
	use_esm: False
HParams:
	add_noise: False
	batch_size: 32
	class_balanced: False
	data_augmentation: True
	lr: 5e-05
	nonlinear_classifier: False
	resnet18: True
	resnet_dropout: 0.0
	weight_decay: 0.0
Device:  cuda
Loading dataset from domainbed/data/abdb.csv
env   target    
env0  HIV1           184
      SARS_CoV_2    1117
env1  HIV1           778
      SARS_CoV_2    3095
env2  HIV1           275
      SARS_CoV_2    1469
env3  HIV1           548
      SARS_CoV_2    3140
Name: target, dtype: int64
Traceback (most recent call last):
  File "/hpc/group/naderilab/imt11/Miniconda3/lib/python3.12/site-packages/pandas/core/indexes/base.py", line 3805, in get_loc
    return self._engine.get_loc(casted_key)
           ^^^^^^^^^^^^^^^^^^^^^^^^^^^^^^^^
  File "index.pyx", line 167, in pandas._libs.index.IndexEngine.get_loc
  File "index.pyx", line 196, in pandas._libs.index.IndexEngine.get_loc
  File "pandas/_libs/hashtable_class_helper.pxi", line 7081, in pandas._libs.hashtable.PyObjectHashTable.get_item
  File "pandas/_libs/hashtable_class_helper.pxi", line 7089, in pandas._libs.hashtable.PyObjectHashTable.get_item
KeyError: 'ag_wt'

The above exception was the direct cause of the following exception:

Traceback (most recent call last):
  File "<frozen runpy>", line 198, in _run_module_as_main
  File "<frozen runpy>", line 88, in _run_code
  File "/hpc/group/naderilab/imt11/antibody-domainbed/domainbed/scripts/train.py", line 111, in <module>
    dataset = vars(datasets)[args.dataset](
              ^^^^^^^^^^^^^^^^^^^^^^^^^^^^^
  File "/hpc/group/naderilab/imt11/antibody-domainbed/domainbed/datasets.py", line 189, in __init__
    target_len = df['ag_wt'].apply(len)
                 ~~^^^^^^^^^
  File "/hpc/group/naderilab/imt11/Miniconda3/lib/python3.12/site-packages/pandas/core/frame.py", line 4102, in __getitem__
    indexer = self.columns.get_loc(key)
              ^^^^^^^^^^^^^^^^^^^^^^^^^
  File "/hpc/group/naderilab/imt11/Miniconda3/lib/python3.12/site-packages/pandas/core/indexes/base.py", line 3812, in get_loc
    raise KeyError(key) from err
KeyError: 'ag_wt'
